Workbook

Sheet Raw_Data
A1: Order ID | B1: Date | C1: Customer | D1: Customer Type | E1: City | F1: Region | G1: Channel | H1: Payment Method | I1: Category | J1: Product | K1: Units Sold | L1: Unit Price | M1: Total Sales
A2: ORD-2001 | B2: 45916 | C2: Nada Hassan | D2: Returning | E2: Rosetta | F2: Alexandria | G2: Website | H2: Wallet | I2: Fashion | J2: T-Shirt | K2: 2 | L2: 1836 | M2: =K2*L2 -> 3672
A3: ORD-2002 | B3: 45844 | C3: Walid Abdelrahman | D3: New | E3: Ismailia | F3: Canal | G3: Mobile App | H3: Credit Card | I3: Sports | J3: Treadmill | K3: 4 | L3: 340 | M3: =K3*L3 -> 1360
A4: ORD-2003 | B4: 45783 | C4: Tarek Hamed | D4: Returning | E4: Mansoura | F4: Delta | G4: Website | H4: Credit Card | I4: Fashion | J4: Dress | K4: 3 | L4: 417 | M4: =K4*L4 -> 1251
A5: ORD-2004 | B5: 46019 | C5: Nada Abdelrahman | D5: Returning | E5: Mahalla | F5: Delta | G5: Website | H5: Wallet | I5: Groceries | J5: Rice Bag | K5: 1 | L5: 383 | M5: =K5*L5 -> 383
A6: ORD-2005 | B6: 45984 | C6: Omar Nasser | D6: VIP | E6: Luxor | F6: Upper Egypt | G6: Website | H6: Cash on Delivery | I6: Books | J6: Self-Help Book | K6: 1 | L6: 213 | M6: =K6*L6 -> 213
A7: ORD-2006 | B7: 45724 | C7: Mahmoud Saleh | D7: Returning | E7: Minya | F7: Upper Egypt | G7: Phone | H7: Wallet | I7: Fashion | J7: Sneakers | K7: 1 | L7: 990 | M7: =K7*L7 -> 990
A8: ORD-2007 | B8: 45861 | C8: Laila Saleh | D8: New | E8: Giza | F8: Cairo | G8: Mobile App | H8: PayPal | I8: Toys | J8: Puzzle Set | K8: 2 | L8: 1449 | M8: =K8*L8 -> 2898
A9: ORD-2008 | B9: 45826 | C9: Laila Saleh | D9: VIP | E9: Luxor | F9: Upper Egypt | G9: Website | H9: Credit Card | I9: Electronics | J9: Smartphone | K9: 5 | L9: 18422 | M9: =K9*L9 -> 92110
A10: ORD-2009 | B10: 45805 | C10: Mai Soliman | D10: New | E10: Giza | F10: Cairo | G10: Phone | H10: Wallet | I10: Toys | J10: Building Blocks | K10: 2 | L10: 859 | M10: =K10*L10 -> 1718
A11: ORD-2010 | B11: 45882 | C11: Farah Nasser | D11: VIP | E11: Assiut | F11: Upper Egypt | G11: Website | H11: Credit Card | I11: Sports | J11: Treadmill | K11: 2 | L11: 7121 | M11: =K11*L11 -> 14242
A12: ORD-2011 | B12: 45899 | C12: Ibrahim Ezzat | D12: Returning | E12: Mansoura | F12: Delta | G12: Social Media | H12: Cash on Delivery | I12: Electronics | J12: Laptop | K12: 5 | L12: 22182 | M12: =K12*L12 -> 110910
A13: ORD-2012 | B13: 45941 | C13: Farah Nasser | D13: VIP | E13: Rosetta | F13: Alexandria | G13: Phone | H13: Wallet | I13: Fashion | J13: Dress | K13: 2 | L13: 1958 | M13: =K13*L13 -> 3916
... A401: ORD-2400 | B401: 45788 | C401: Khaled Hassan | D401: VIP | E401: Ismailia | F401: Canal | G401: Website | H401: Credit Card | I401: Electronics | J401: Smartphone | K401: 2 | L401: 18994 | M401: =K401*L401 -> 37988

Sheet Summary
A1: E-Commerce Sales Analytics - Summary
A4: 1) Sales by Region
A5: Region | B5: Total Sales | C5: Orders | D5: Avg Order Value
A6: Cairo | B6: =SUMIFS(Raw_Data!$M$2:$M$401,Raw_Data!$F$2:$F$401,$A6) -> 600111 | C6: =COUNTIFS(Raw_Data!$F$2:$F$401,$A6) -> 68 | D6: =IFERROR(B6/C6,0) -> 8825.1618
A7: Delta | B7: =SUMIFS(Raw_Data!$M$2:$M$401,Raw_Data!$F$2:$F$401,$A7) -> 461366 | C7: =COUNTIFS(Raw_Data!$F$2:$F$401,$A7) -> 69 | D7: =IFERROR(B7/C7,0) -> 6686.4638
A8: Alexandria | B8: =SUMIFS(Raw_Data!$M$2:$M$401,Raw_Data!$F$2:$F$401,$A8) -> 390559 | C8: =COUNTIFS(Raw_Data!$F$2:$F$401,$A8) -> 55 | D8: =IFERROR(B8/C8,0) -> 7101.0727
A9: Canal | B9: =SUMIFS(Raw_Data!$M$2:$M$401,Raw_Data!$F$2:$F$401,$A9) -> 521612 | C9: =COUNTIFS(Raw_Data!$F$2:$F$401,$A9) -> 68 | D9: =IFERROR(B9/C9,0) -> 7670.7647
A10: Upper Egypt | B10: =SUMIFS(Raw_Data!$M$2:$M$401,Raw_Data!$F$2:$F$401,$A10) -> 1521280 | C10: =COUNTIFS(Raw_Data!$F$2:$F$401,$A10) -> 140 | D10: =IFERROR(B10/C10,0) -> 10866.286
A11: 2) Sales by Category
A12: Category | B12: Total Sales | C12: Units Sold | D12: % of Total
A13: Electronics | B13: =SUMIFS(Raw_Data!$M$2:$M$401,Raw_Data!$I$2:$I$401,$A13) -> 1657187 | C13: =SUMIFS(Raw_Data!$K$2:$K$401,Raw_Data!$I$2:$I$401,$A13) -> 119 | D13: =IFERROR(B13/SUM(Raw_Data!$M$2:$M$401),0) -> 0.47416914
A14: Fashion | B14: =SUMIFS(Raw_Data!$M$2:$M$401,Raw_Data!$I$2:$I$401,$A14) -> 220070 | C14: =SUMIFS(Raw_Data!$K$2:$K$401,Raw_Data!$I$2:$I$401,$A14) -> 150 | D14: =IFERROR(B14/SUM(Raw_Data!$M$2:$M$401),0) -> 0.062968393
A15: Home & Kitchen | B15: =SUMIFS(Raw_Data!$M$2:$M$401,Raw_Data!$I$2:$I$401,$A15) -> 528620 | C15: =SUMIFS(Raw_Data!$K$2:$K$401,Raw_Data!$I$2:$I$401,$A15) -> 173 | D15: =IFERROR(B15/SUM(Raw_Data!$M$2:$M$401),0) -> 0.15125347
A16: Beauty | B16: =SUMIFS(Raw_Data!$M$2:$M$401,Raw_Data!$I$2:$I$401,$A16) -> 171344 | C16: =SUMIFS(Raw_Data!$K$2:$K$401,Raw_Data!$I$2:$I$401,$A16) -> 150 | D16: =IFERROR(B16/SUM(Raw_Data!$M$2:$M$401),0) -> 0.049026475
A17: Sports | B17: =SUMIFS(Raw_Data!$M$2:$M$401,Raw_Data!$I$2:$I$401,$A17) -> 739404 | C17: =SUMIFS(Raw_Data!$K$2:$K$401,Raw_Data!$I$2:$I$401,$A17) -> 166 | D17: =IFERROR(B17/SUM(Raw_Data!$M$2:$M$401),0) -> 0.21156487
A18: Books | B18: =SUMIFS(Raw_Data!$M$2:$M$401,Raw_Data!$I$2:$I$401,$A18) -> 49045 | C18: =SUMIFS(Raw_Data!$K$2:$K$401,Raw_Data!$I$2:$I$401,$A18) -> 143 | D18: =IFERROR(B18/SUM(Raw_Data!$M$2:$M$401),0) -> 0.014033193
A19: Groceries | B19: =SUMIFS(Raw_Data!$M$2:$M$401,Raw_Data!$I$2:$I$401,$A19) -> 37609 | C19: =SUMIFS(Raw_Data!$K$2:$K$401,Raw_Data!$I$2:$I$401,$A19) -> 156 | D19: =IFERROR(B19/SUM(Raw_Data!$M$2:$M$401),0) -> 0.010761023
A20: 3) Sales by Channel | B20: =SUMIFS(Raw_Data!$M$2:$M$401,Raw_Data!$I$2:$I$401,$A20) -> 0 | C20: =SUMIFS(Raw_Data!$K$2:$K$401,Raw_Data!$I$2:$I$401,$A20) -> 0 | D20: =IFERROR(B20/SUM(Raw_Data!$M$2:$M$401),0) -> 0
A21: Channel | B21: Total Sales | C21: Orders | D21: Avg
A22: Website | B22: =SUMIFS(Raw_Data!$M$2:$M$401,Raw_Data!$G$2:$G$401,$A22) -> 1232865 | C22: =COUNTIFS(Raw_Data!$G$2:$G$401,$A22) -> 154 | D22: =IFERROR(B22/C22,0) -> 8005.6169
A23: Mobile App | B23: =SUMIFS(Raw_Data!$M$2:$M$401,Raw_Data!$G$2:$G$401,$A23) -> 1322523 | C23: =COUNTIFS(Raw_Data!$G$2:$G$401,$A23) -> 164 | D23: =IFERROR(B23/C23,0) -> 8064.1646
A24: Social Media | B24: =SUMIFS(Raw_Data!$M$2:$M$401,Raw_Data!$G$2:$G$401,$A24) -> 564317 | C24: =COUNTIFS(Raw_Data!$G$2:$G$401,$A24) -> 40 | D24: =IFERROR(B24/C24,0) -> 14107.925
A25: Phone | B25: =SUMIFS(Raw_Data!$M$2:$M$401,Raw_Data!$G$2:$G$401,$A25) -> 375223 | C25: =COUNTIFS(Raw_Data!$G$2:$G$401,$A25) -> 42 | D25: =IFERROR(B25/C25,0) -> 8933.881
A27: 4) Monthly Sales Trend
A28: Month | B28: Total Sales
A29: January | B29: =SUMPRODUCT((MONTH(Raw_Data!$B$2:$B$401)=1)*Raw_Data!$M$2:$M$401) -> 250689
A30: February | B30: =SUMPRODUCT((MONTH(Raw_Data!$B$2:$B$401)=2)*Raw_Data!$M$2:$M$401) -> 243228
A31: March | B31: =SUMPRODUCT((MONTH(Raw_Data!$B$2:$B$401)=3)*Raw_Data!$M$2:$M$401) -> 312835
A32: April | B32: =SUMPRODUCT((MONTH(Raw_Data!$B$2:$B$401)=4)*Raw_Data!$M$2:$M$401) -> 213849
A33: May | B33: =SUMPRODUCT((MONTH(Raw_Data!$B$2:$B$401)=5)*Raw_Data!$M$2:$M$401) -> 384355
A34: June | B34: =SUMPRODUCT((MONTH(Raw_Data!$B$2:$B$401)=6)*Raw_Data!$M$2:$M$401) -> 438231
A35: July | B35: =SUMPRODUCT((MONTH(Raw_Data!$B$2:$B$401)=7)*Raw_Data!$M$2:$M$401) -> 205963
A36: August | B36: =SUMPRODUCT((MONTH(Raw_Data!$B$2:$B$401)=8)*Raw_Data!$M$2:$M$401) -> 591748
A37: September | B37: =SUMPRODUCT((MONTH(Raw_Data!$B$2:$B$401)=9)*Raw_Data!$M$2:$M$401) -> 124855
A38: October | B38: =SUMPRODUCT((MONTH(Raw_Data!$B$2:$B$401)=10)*Raw_Data!$M$2:$M$401) -> 398809
A39: November | B39: =SUMPRODUCT((MONTH(Raw_Data!$B$2:$B$401)=11)*Raw_Data!$M$2:$M$401) -> 135285
A40: December | B40: =SUMPRODUCT((MONTH(Raw_Data!$B$2:$B$401)=12)*Raw_Data!$M$2:$M$401) -> 195081
A41: 5) Sales by Customer Type
A42: Customer Type | B42: Total Sales | C42: Orders
A43: New | B43: =SUMIFS(Raw_Data!$M$2:$M$401,Raw_Data!$D$2:$D$401,$A43) -> 1189838 | C43: =COUNTIFS(Raw_Data!$D$2:$D$401,$A43) -> 138
...

Sheet Dashboard
A1: E-Commerce Sales Analytics Dashboard
A3: Total Sales | B3: Total Orders | C3: Avg Order Value | D3: Total Units | E3: Top Category | F3: Top Product
A4: =SUM(Raw_Data!M2:M401) -> 3494928 | B4: =COUNTA(Raw_Data!A2:A401) -> 400 | C4: =IFERROR(AVERAGE(Raw_Data!M2:M401),0) -> 8737.32 | D4: =SUM(Raw_Data!K2:K401) -> 1191 | E4: =INDEX(Summary!$A$13:$A$20,MATCH(MAX(Summary!$B$13:$B$20),Summary!$B$13:$B$20,0)) -> Electronics | F4: =INDEX(Summary!$A$48:$A$78,MATCH(LARGE(Summary!$B$48:$B$78,1),Summary!$B$48:$B$78,0)) -> Smartphone
